<?xml version="1.0" ?>
<sdf version="1.10">
  <world name="minimal_diff_drive">
    <physics name="1ms" type="ignored">
      <max_step_size>0.001</max_step_size>
      <real_time_factor>1.0</real_time_factor>
    </physics>

    <plugin filename="gz-sim-physics-system" name="gz::sim::systems::Physics" />
    <plugin filename="gz-sim-user-commands-system" name="gz::sim::systems::UserCommands" />
    <plugin filename="gz-sim-scene-broadcaster-system" name="gz::sim::systems::SceneBroadcaster" />
    <plugin filename="gz-sim-sensors-system" name="gz::sim::systems::Sensors">
      <render_engine>ogre2</render_engine>
    </plugin>

    <light type="directional" name="sun">
      <cast_shadows>true</cast_shadows>
      <pose>0 0 10 0 0 0</pose>
      <diffuse>0.8 0.8 0.8 1</diffuse>
      <specular>0.2 0.2 0.2 1</specular>
      <attenuation>
        <range>1000</range>
        <constant>0.9</constant>
        <linear>0.01</linear>
        <quadratic>0.001</quadratic>
      </attenuation>
      <direction>-0.5 0.1 -0.9</direction>
    </light>

    <model name="ground_plane">
      <static>true</static>
      <link name="ground_link">
        <collision name="ground_collision">
          <geometry>
            <plane>
              <normal>0 0 1</normal>
              <size>100 100</size>
            </plane>
          </geometry>
        </collision>
        <visual name="ground_visual">
          <geometry>
            <plane>
              <normal>0 0 1</normal>
              <size>100 100</size>
            </plane>
          </geometry>
          <material>
            <ambient>0.8 0.8 0.8 1</ambient>
            <diffuse>0.8 0.8 0.8 1</diffuse>
          </material>
        </visual>
      </link>
    </model>

    <model name="minibot">
      <pose>0 0 0 0 0 0</pose>

      <link name="chassis">
        <pose>0 0 0.14 0 0 0</pose>
        <inertial>
          <mass>5.0</mass>
          <inertia>
            <ixx>0.12</ixx>
            <iyy>0.20</iyy>
            <izz>0.25</izz>
            <ixy>0.0</ixy>
            <ixz>0.0</ixz>
            <iyz>0.0</iyz>
          </inertia>
        </inertial>
        <collision name="chassis_collision">
          <geometry>
            <box>
              <size>0.45 0.30 0.08</size>
            </box>
          </geometry>
        </collision>
        <visual name="chassis_visual">
          <geometry>
            <box>
              <size>0.45 0.30 0.08</size>
            </box>
          </geometry>
          <material>
            <ambient>0.2 0.4 0.7 1</ambient>
            <diffuse>0.2 0.4 0.7 1</diffuse>
          </material>
        </visual>
        <sensor name="front_lidar" type="gpu_lidar">
          <pose>0.23 0 0.08 0 0 0</pose>
          <topic>/model/minibot/scan</topic>
          <update_rate>10</update_rate>
          <lidar>
            <scan>
              <horizontal>
                <samples>180</samples>
                <resolution>1</resolution>
                <min_angle>-1.57079632679</min_angle>
                <max_angle>1.57079632679</max_angle>
              </horizontal>
            </scan>
            <range>
              <min>0.08</min>
              <max>5.0</max>
              <resolution>0.01</resolution>
            </range>
          </lidar>
          <always_on>true</always_on>
          <visualize>true</visualize>
        </sensor>
      </link>

      <link name="left_wheel">
        <pose>0 0.18 0.08 1.57079632679 0 0</pose>
        <inertial>
          <mass>0.5</mass>
          <inertia>
            <ixx>0.001</ixx>
            <iyy>0.001</iyy>
            <izz>0.001</izz>
            <ixy>0.0</ixy>
            <ixz>0.0</ixz>
            <iyz>0.0</iyz>
          </inertia>
        </inertial>
        <collision name="left_wheel_collision">
          <geometry>
            <cylinder>
              <radius>0.08</radius>
              <length>0.05</length>
            </cylinder>
          </geometry>
          <surface>
            <friction>
              <ode>
                <mu>1.5</mu>
                <mu2>1.5</mu2>
              </ode>
            </friction>
          </surface>
        </collision>
        <visual name="left_wheel_visual">
          <geometry>
            <cylinder>
              <radius>0.08</radius>
              <length>0.05</length>
            </cylinder>
          </geometry>
          <material>
            <ambient>0.1 0.1 0.1 1</ambient>
            <diffuse>0.1 0.1 0.1 1</diffuse>
          </material>
        </visual>
      </link>

      <link name="right_wheel">
        <pose>0 -0.18 0.08 1.57079632679 0 0</pose>
        <inertial>
          <mass>0.5</mass>
          <inertia>
            <ixx>0.001</ixx>
            <iyy>0.001</iyy>
            <izz>0.001</izz>
            <ixy>0.0</ixy>
            <ixz>0.0</ixz>
            <iyz>0.0</iyz>
          </inertia>
        </inertial>
        <collision name="right_wheel_collision">
          <geometry>
            <cylinder>
              <radius>0.08</radius>
              <length>0.05</length>
            </cylinder>
          </geometry>
          <surface>
            <friction>
              <ode>
                <mu>1.5</mu>
                <mu2>1.5</mu2>
              </ode>
            </friction>
          </surface>
        </collision>
        <visual name="right_wheel_visual">
          <geometry>
            <cylinder>
              <radius>0.08</radius>
              <length>0.05</length>
            </cylinder>
          </geometry>
          <material>
            <ambient>0.1 0.1 0.1 1</ambient>
            <diffuse>0.1 0.1 0.1 1</diffuse>
          </material>
        </visual>
      </link>

      <link name="front_caster">
        <pose>0.17 0 0.03 0 0 0</pose>
        <inertial>
          <mass>0.1</mass>
          <inertia>
            <ixx>0.0001</ixx>
            <iyy>0.0001</iyy>
            <izz>0.0001</izz>
            <ixy>0.0</ixy>
            <ixz>0.0</ixz>
            <iyz>0.0</iyz>
          </inertia>
        </inertial>
        <collision name="front_caster_collision">
          <geometry>
            <sphere>
              <radius>0.03</radius>
            </sphere>
          </geometry>
          <surface>
            <friction>
              <ode>
                <mu>0.05</mu>
                <mu2>0.05</mu2>
              </ode>
            </friction>
          </surface>
        </collision>
        <visual name="front_caster_visual">
          <geometry>
            <sphere>
              <radius>0.03</radius>
            </sphere>
          </geometry>
        </visual>
      </link>

      <link name="rear_caster">
        <pose>-0.17 0 0.03 0 0 0</pose>
        <inertial>
          <mass>0.1</mass>
          <inertia>
            <ixx>0.0001</ixx>
            <iyy>0.0001</iyy>
            <izz>0.0001</izz>
            <ixy>0.0</ixy>
            <ixz>0.0</ixz>
            <iyz>0.0</iyz>
          </inertia>
        </inertial>
        <collision name="rear_caster_collision">
          <geometry>
            <sphere>
              <radius>0.03</radius>
            </sphere>
          </geometry>
          <surface>
            <friction>
              <ode>
                <mu>0.05</mu>
                <mu2>0.05</mu2>
              </ode>
            </friction>
          </surface>
        </collision>
        <visual name="rear_caster_visual">
          <geometry>
            <sphere>
              <radius>0.03</radius>
            </sphere>
          </geometry>
        </visual>
      </link>

      <joint name="left_wheel_joint" type="revolute">
        <parent>chassis</parent>
        <child>left_wheel</child>
        <axis>
          <xyz>0 0 1</xyz>
          <limit>
            <lower>-1e16</lower>
            <upper>1e16</upper>
          </limit>
        </axis>
      </joint>

      <joint name="right_wheel_joint" type="revolute">
        <parent>chassis</parent>
        <child>right_wheel</child>
        <axis>
          <xyz>0 0 1</xyz>
          <limit>
            <lower>-1e16</lower>
            <upper>1e16</upper>
          </limit>
        </axis>
      </joint>

      <joint name="front_caster_joint" type="fixed">
        <parent>chassis</parent>
        <child>front_caster</child>
      </joint>

      <joint name="rear_caster_joint" type="fixed">
        <parent>chassis</parent>
        <child>rear_caster</child>
      </joint>

      <plugin filename="gz-sim-diff-drive-system" name="gz::sim::systems::DiffDrive">
        <left_joint>left_wheel_joint</left_joint>
        <right_joint>right_wheel_joint</right_joint>
        <wheel_separation>0.36</wheel_separation>
        <wheel_radius>0.08</wheel_radius>
        <odom_publish_frequency>30</odom_publish_frequency>
        <topic>/model/minibot/cmd_vel</topic>
        <odom_topic>/model/minibot/odometry</odom_topic>
        <frame_id>odom</frame_id>
        <child_frame_id>base_link</child_frame_id>
        <max_linear_acceleration>1.0</max_linear_acceleration>
        <max_angular_acceleration>1.5</max_angular_acceleration>
      </plugin>
    </model>
  </world>
</sdf>
